#VRML_SIM R2023a utf8

EXTERNPROTO "https://raw.githubusercontent.com/cyberbotics/webots/R2022b/projects/objects/backgrounds/protos/TexturedBackground.proto"
EXTERNPROTO "https://raw.githubusercontent.com/cyberbotics/webots/R2022b/projects/objects/backgrounds/protos/TexturedBackgroundLight.proto"
EXTERNPROTO "https://raw.githubusercontent.com/cyberbotics/webots/R2022b/projects/objects/factory/containers/protos/WoodenBox.proto"
EXTERNPROTO "https://raw.githubusercontent.com/cyberbotics/webots/R2022b/projects/objects/floors/protos/Floor.proto"

WorldInfo {
  basicTimeStep 16
}
Viewpoint {
  orientation -0.4235513213228956 -0.38330514138581995 0.8207809980700246 4.382730625468442
  position 0.09601517939903707 1.5808693507690559 2.602186945378743
}
TexturedBackground {
}
TexturedBackgroundLight {
}
WoodenBox {
  translation 0 0.26 0.05
  size 0.1 0.1 0.1
}
WoodenBox {
  translation 0.24 -0.18 0.05
  name "wooden box(2)"
  size 0.1 0.1 0.1
}
WoodenBox {
  translation -0.25 -0.25 0.05
  rotation 0 1 0 0
  name "wooden box(1)"
  size 0.1 0.1 0.1
}
Floor {
  size 1 1
}
Solid {
  translation 0.272945278351155 0.3568185502564639 0.049589079680910385
  rotation 0.674436503463838 0.11476126214345607 -0.7293594830443446 -1.3185484640337464
  children [
    Shape {
      appearance PBRAppearance {
        baseColor 0.666667 0.333333 0
        roughness 1
        metalness 0
      }
      geometry DEF BALL_GEOMETRY Sphere {
        radius 0.05
      }
    }
  ]
  name "Ball"
  boundingObject USE BALL_GEOMETRY
  physics Physics {
  }
  linearVelocity -0.09569877609087817 0.07585078654175345 1.1681410833313676e-15
  angularVelocity -1.517015730835069 -1.9139755218175634 -1.6596867695266173
}
Solid {
  translation -0.4111528862098837 -0.06531108685646995 0.04958919553758353
  rotation 0.026819874594189573 0.04513822059715441 -0.9986206664034519 -2.7273144052739298
  children [
    Shape {
      appearance PBRAppearance {
        roughness 1
        metalness 0
      }
      geometry DEF BALL_GEOMETRY Sphere {
        radius 0.05
      }
    }
  ]
  name "Ball(1)"
  boundingObject USE BALL_GEOMETRY
  physics Physics {
  }
  linearVelocity 0.13464864473178773 0.0938672257314848 -1.8291618238661826e-06
  angularVelocity -1.877344514629696 2.6929728946357545 2.0904630670079807
}
Solid {
  translation 0 0.55 0.05
  children [
    Shape {
      appearance PBRAppearance {
        metalness 0
      }
      geometry DEF WALL_GEOMETRY Box {
        size 1 0.1 0.1
      }
    }
  ]
  name "Wall 1"
  boundingObject USE WALL_GEOMETRY
}
Solid {
  translation 0 -0.55 0.05
  children [
    Shape {
      appearance PBRAppearance {
        metalness 0
      }
      geometry DEF WALL_GEOMETRY Box {
        size 1 0.1 0.1
      }
    }
  ]
  name "Wall 2"
  boundingObject USE WALL_GEOMETRY
}
Solid {
  translation -0.55 -2.02023e-06 0.05
  rotation 0 0 1 1.5708
  children [
    Shape {
      appearance PBRAppearance {
        metalness 0
      }
      geometry DEF WALL_GEOMETRY Box {
        size 1 0.1 0.1
      }
    }
  ]
  name "Wall 3"
  boundingObject USE WALL_GEOMETRY
}
Solid {
  translation 0.55 2.02018e-06 0.05
  rotation 0 0 1 1.5708
  children [
    Shape {
      appearance PBRAppearance {
        metalness 0
      }
      geometry DEF WALL_GEOMETRY Box {
        size 1 0.1 0.1
      }
    }
  ]
  name "Wall 4"
  boundingObject USE WALL_GEOMETRY
}
Robot {
  translation -0.14082106049503645 0.13579344468695242 0.039760136358173825
  rotation -2.4188686209364924e-05 -6.52357490337226e-05 -0.9999999975796022 1.1603187409565743
  children [
    DistanceSensor {
      translation 0.1 0.02 0
      rotation 0 0 1 0.3
      children [
        Solid {
          children [
            DEF DS Shape {
              appearance PBRAppearance {
                baseColor 0 0 1
              }
              geometry Box {
                size 0.01 0.01 0.01
              }
            }
          ]
        }
      ]
      name "ds_2"
      boundingObject USE DS
      physics DEF DS_PH Physics {
      }
    }
    DistanceSensor {
      translation 0.1 -0.02 0
      rotation 0 0 1 -0.3
      children [
        Solid {
          children [
            USE DS
          ]
        }
      ]
      name "ds_1"
      boundingObject USE DS
      physics DEF DS_PH Physics {
      }
    }
    HingeJoint {
      jointParameters HingeJointParameters {
        position 254.43063293475896
        axis 0 1 0
        anchor 0.05 0.06 0
      }
      device [
        RotationalMotor {
          name "wheel_1"
        }
      ]
      endPoint DEF WHEEL_1 Solid {
        translation 0.0500000752717084 0.05999999999981208 -1.9606679195147838e-06
        rotation 0.013566993850253192 0.707040403426716 -0.7070430005311232 3.1144604301460888
        children [
          DEF Wheel Shape {
            appearance PBRAppearance {
              baseColor 0 1 0
            }
            geometry Cylinder {
              height 0.02
              radius 0.04
            }
          }
        ]
        name "solid(1)"
        boundingObject USE Wheel
        physics DEF Wheel_1 Physics {
        }
        linearVelocity 0.015912337676908375 -0.03671920014451217 -5.063598238547495e-05
        angularVelocity 0.9187293780791558 0.3981050113449934 -0.00018315967711807088
      }
    }
    HingeJoint {
      jointParameters HingeJointParameters {
        position 43.751659257740116
        axis 0 1 0
        anchor 0.05 -0.06 0
      }
      device [
        RotationalMotor {
          name "wheel_2"
        }
      ]
      endPoint DEF WHEEL_1 Solid {
        translation 0.049999551515459914 -0.06000000000018793 1.909937636754792e-06
        rotation -0.9868469279423349 0.11430889033353159 -0.11430931021352854 4.699145354564187
        children [
          DEF Wheel Shape {
            appearance PBRAppearance {
              baseColor 0 1 0
            }
            geometry Cylinder {
              height 0.02
              radius 0.04
            }
          }
        ]
        name "solid(2)"
        boundingObject USE Wheel
        physics DEF Wheel_1 Physics {
        }
        linearVelocity 0.0159966041276701 -0.03670811279884092 -7.391518449847359e-05
        angularVelocity 0.9176236615006783 0.4006503156596112 1.6650475269175074e-05
      }
    }
    HingeJoint {
      jointParameters HingeJointParameters {
        position 260.0447804805928
        axis 0 1 0
        anchor -0.05 0.06 0
      }
      device [
        RotationalMotor {
          name "wheel_3"
        }
      ]
      endPoint DEF WHEEL_1 Solid {
        translation -0.04999872488749587 0.059999999999812065 -1.4912989715187888e-06
        rotation -0.2526192829272628 -0.6841710528463052 0.6841735659468974 3.6364756035338264
        children [
          DEF Wheel Shape {
            appearance PBRAppearance {
              baseColor 0 1 0
            }
            geometry Cylinder {
              height 0.02
              radius 0.04
            }
          }
        ]
        name "solid(3)"
        boundingObject USE Wheel
        physics DEF Wheel_1 Physics {
        }
        linearVelocity 0.01595419523098598 -0.03674612301604104 7.330322036488111e-05
        angularVelocity 0.9187327706203361 0.39810533759377936 -0.00018343201177803843
      }
    }
    HingeJoint {
      jointParameters HingeJointParameters {
        position 43.75167519981762
        axis 0 1 0
        anchor -0.05 -0.06 0
      }
      device [
        RotationalMotor {
          name "wheel_4"
        }
      ]
      endPoint DEF WHEEL_1 Solid {
        translation -0.05000044845409166 -0.06000000000018793 1.9099447863153696e-06
        rotation -0.9868487263926666 0.11430112693670333 -0.11430154678818424 4.699147176823493
        children [
          DEF Wheel Shape {
            appearance PBRAppearance {
              baseColor 0 1 0
            }
            geometry Cylinder {
              height 0.02
              radius 0.04
            }
          }
        ]
        name "solid(4)"
        boundingObject USE Wheel
        physics DEF Wheel_1 Physics {
        }
        linearVelocity 0.016037729392037067 -0.03673686868860049 5.119859353849061e-05
        angularVelocity 0.9176270313802861 0.40065067724832376 1.6569726779008564e-05
      }
    }
    Solid {
      children [
        DEF Body Shape {
          appearance PBRAppearance {
            baseColor 1 0 0
          }
          geometry Box {
            size 0.2 0.1 0.05
          }
        }
      ]
      boundingObject USE Body
      physics Physics {
      }
    }
  ]
  boundingObject USE Body
  physics Physics {
  }
  controller "control_robot"
  linearVelocity 0.015975349468916978 -0.03672862323289516 -2.667456729743152e-08
  angularVelocity 0.0012509110968688725 0.0003235396204373296 1.2349502035079219e-05
}
