#VRML_SIM R2022b utf8

EXTERNPROTO "https://raw.githubusercontent.com/cyberbotics/webots/R2022b/projects/objects/backgrounds/protos/TexturedBackground.proto"
EXTERNPROTO "https://raw.githubusercontent.com/cyberbotics/webots/R2022b/projects/objects/backgrounds/protos/TexturedBackgroundLight.proto"
EXTERNPROTO "https://raw.githubusercontent.com/cyberbotics/webots/R2022b/projects/objects/factory/containers/protos/WoodenBox.proto"
EXTERNPROTO "https://raw.githubusercontent.com/cyberbotics/webots/R2022b/projects/objects/floors/protos/Floor.proto"

WorldInfo {
  basicTimeStep 16
}
Viewpoint {
  orientation -0.20503180479944194 -0.6854557547687499 0.6986503898768588 5.40330927113541
  position -1.3888168298345027 0.9874035672422219 1.1522356412393542
}
TexturedBackground {
}
TexturedBackgroundLight {
}
WoodenBox {
  translation 0 0.26 0.05
  size 0.1 0.1 0.1
}
WoodenBox {
  translation 0.24 -0.18 0.05
  name "wooden box(2)"
  size 0.1 0.1 0.1
}
WoodenBox {
  translation -0.25 -0.25 0.05
  rotation 0 1 0 0
  name "wooden box(1)"
  size 0.1 0.1 0.1
}
Floor {
  size 1 1
}
Solid {
  translation 0.23108954430188172 0.4100582294187615 0.04958907968091044
  rotation -0.11417562604787337 0.9241365434267858 0.36460331254634637 -2.7046667835000004
  children [
    Shape {
      appearance PBRAppearance {
        baseColor 0.666667 0.333333 0
        roughness 1
        metalness 0
      }
      geometry DEF BALL_GEOMETRY Sphere {
        radius 0.05
      }
    }
  ]
  name "Ball"
  boundingObject USE BALL_GEOMETRY
  physics Physics {
  }
}
Solid {
  translation -0.2972108267316404 -0.3697993676886519 0.04958907968091044
  rotation -0.1766972222692063 -0.4185996553800494 -0.8908155926778846 -2.369717421129204
  children [
    Shape {
      appearance PBRAppearance {
        roughness 1
        metalness 0
      }
      geometry DEF BALL_GEOMETRY Sphere {
        radius 0.05
      }
    }
  ]
  name "Ball(1)"
  boundingObject USE BALL_GEOMETRY
  physics Physics {
  }
}
Solid {
  translation 0 0.55 0.05
  children [
    Shape {
      appearance PBRAppearance {
        metalness 0
      }
      geometry DEF WALL_GEOMETRY Box {
        size 1 0.1 0.1
      }
    }
  ]
  name "Wall 1"
  boundingObject USE WALL_GEOMETRY
}
Solid {
  translation 0 -0.55 0.05
  children [
    Shape {
      appearance PBRAppearance {
        metalness 0
      }
      geometry DEF WALL_GEOMETRY Box {
        size 1 0.1 0.1
      }
    }
  ]
  name "Wall 2"
  boundingObject USE WALL_GEOMETRY
}
Solid {
  translation -0.55 -2.02023e-06 0.05
  rotation 0 0 1 1.5708
  children [
    Shape {
      appearance PBRAppearance {
        metalness 0
      }
      geometry DEF WALL_GEOMETRY Box {
        size 1 0.1 0.1
      }
    }
  ]
  name "Wall 3"
  boundingObject USE WALL_GEOMETRY
}
Solid {
  translation 0.55 2.02018e-06 0.05
  rotation 0 0 1 1.5708
  children [
    Shape {
      appearance PBRAppearance {
        metalness 0
      }
      geometry DEF WALL_GEOMETRY Box {
        size 1 0.1 0.1
      }
    }
  ]
  name "Wall 4"
  boundingObject USE WALL_GEOMETRY
}
Robot {
  translation -0.13111149683578655 -0.13378638593771194 0.03975646608770065
  rotation -0.0008667837787968516 -0.0008207031414222886 -0.9999992875658635 -1.5830957828157146
  children [
    DistanceSensor {
      translation 0.1 0.02 0
      rotation 0 0 1 0.3
      children [
        Solid {
          children [
            DEF DS Shape {
              appearance PBRAppearance {
                baseColor 0 0 1
              }
              geometry Box {
                size 0.01 0.01 0.01
              }
            }
          ]
        }
      ]
      name "ds_2"
      boundingObject USE DS
      physics DEF DS_PH Physics {
      }
    }
    DistanceSensor {
      translation 0.1 -0.02 0
      rotation 0 0 1 -0.3
      children [
        Solid {
          children [
            USE DS
          ]
        }
      ]
      name "ds_1"
      boundingObject USE DS
      physics DEF DS_PH Physics {
      }
    }
    HingeJoint {
      jointParameters HingeJointParameters {
        position 241.93464866179528
        axis 0 1 0
        anchor 0.05 0.06 0
      }
      device [
        RotationalMotor {
          name "wheel_1"
        }
      ]
      endPoint DEF WHEEL_1 Solid {
        translation 0.0499999371950096 0.05999999999981208 -1.9611068440752157e-06
        rotation -0.011319039281409203 0.7070601836555417 -0.7070627808326057 3.164229682281796
        children [
          DEF Wheel Shape {
            appearance PBRAppearance {
              baseColor 0 1 0
            }
            geometry Cylinder {
              height 0.02
              radius 0.04
            }
          }
        ]
        name "solid(1)"
        boundingObject USE Wheel
        physics DEF Wheel_1 Physics {
        }
      }
    }
    HingeJoint {
      jointParameters HingeJointParameters {
        position 44.05564335345351
        axis 0 1 0
        anchor 0.05 -0.06 0
      }
      device [
        RotationalMotor {
          name "wheel_2"
        }
      ]
      endPoint DEF WHEEL_1 Solid {
        translation 0.05000014376796946 -0.06000000000018793 1.9566121051321535e-06
        rotation -0.9986565937442942 -0.036640127650416444 0.03664026223712014 4.711040998159705
        children [
          DEF Wheel Shape {
            appearance PBRAppearance {
              baseColor 0 1 0
            }
            geometry Cylinder {
              height 0.02
              radius 0.04
            }
          }
        ]
        name "solid(2)"
        boundingObject USE Wheel
        physics DEF Wheel_1 Physics {
        }
      }
    }
    HingeJoint {
      jointParameters HingeJointParameters {
        position 247.54879651996612
        axis 0 1 0
        anchor -0.05 0.06 0
      }
      device [
        RotationalMotor {
          name "wheel_3"
        }
      ]
      endPoint DEF WHEEL_1 Solid {
        translation -0.04999883292571753 0.059999999999812065 -1.577283151447886e-06
        rotation -0.22707010247088966 -0.6886347670422539 0.6886372965389839 3.5881589072512083
        children [
          DEF Wheel Shape {
            appearance PBRAppearance {
              baseColor 0 1 0
            }
            geometry Cylinder {
              height 0.02
              radius 0.04
            }
          }
        ]
        name "solid(3)"
        boundingObject USE Wheel
        physics DEF Wheel_1 Physics {
        }
      }
    }
    HingeJoint {
      jointParameters HingeJointParameters {
        position 44.05565919990371
        axis 0 1 0
        anchor -0.05 -0.06 0
      }
      device [
        RotationalMotor {
          name "wheel_4"
        }
      ]
      endPoint DEF WHEEL_1 Solid {
        translation -0.0499998562010252 -0.06000000000018793 1.9566098267017226e-06
        rotation -0.998656013845456 -0.036648029575162146 0.036648164190890856 4.711040417481137
        children [
          DEF Wheel Shape {
            appearance PBRAppearance {
              baseColor 0 1 0
            }
            geometry Cylinder {
              height 0.02
              radius 0.04
            }
          }
        ]
        name "solid(4)"
        boundingObject USE Wheel
        physics DEF Wheel_1 Physics {
        }
      }
    }
    Solid {
      children [
        DEF Body Shape {
          appearance PBRAppearance {
            baseColor 1 0 0
          }
          geometry Box {
            size 0.2 0.1 0.05
          }
        }
      ]
      boundingObject USE Body
      physics Physics {
      }
    }
  ]
  boundingObject USE Body
  physics Physics {
  }
  controller "control_robot"
}
